<mujoco model="inverted pendulum">
	<compiler inertiafromgeom="true" />
	<default>
		<joint armature="0" damping="1" limited="true" />
		<geom contype="0" friction="9 9 9" rgba="0.9 0.7 0 0.5" />
		<tendon />
		<motor ctrlrange="-3 3" />
	</default>

	<visual>
		<headlight diffuse="0.6 0.6 0.6" ambient="0.8 0.8 0.8" specular="0 0 0" />
		<rgba haze="0.35 0.35 0.35 1" />
		<global azimuth="150" elevation="-20" />
	</visual>
	<option gravity="0 0 -9.81" integrator="implicitfast" timestep="0.02" />
	<size nstack="3000" />
	<worldbody>
		<!-- <light name="top" pos="0 -1 1" specular="1 1 1" diffuse="9 9 9" dir="0 1 -1" /> -->
		<!-- light name="to2" pos="-1 -1 0" specular="1 1 1" diffuse="9 9 9" dir="1 1 0"/ -->
		<!--geom
		name="ground" type="plane" pos="0 0 0" /-->
		<geom name="rail" pos="0 0 0" quat="0.707 0 0.707 0" rgba="0.3 0.3 0.7 1" size="0.02 1"
			type="capsule" />
		<body name="cart" pos="0 0 0">
			<joint axis="1 0 0" limited="true" name="slider" pos="0 0 0" range="-1 1" type="slide" />
			<geom name="cart" pos="0 0 0" quat="0.707 0 0.707 0" size="0.05 0.05" type="capsule" />
			<body name="pole" pos="0 0 0">
				<joint axis="1 0 1" name="hinge" pos="0 0 0.01" range="-90 90" type="hinge" />
				<geom fromto="0 0 0 0.001 0 0.6" name="cpole" rgba="0 0.7 0.7 1" size="0.049 0.3"
					type="capsule" />
				<!--                 <body name="pole2" pos="0.001 0 0.6"><joint name="hinge2" type="hinge" pos="0 0
				0" axis="0 1 0"/><geom name="cpole2" type="capsule" fromto="0 0 0 0 0 0.6"
				size="0.05 0.3" rgba="0.7 0 0.7 1"/><site name="tip2" pos="0 0 .6"/></body>-->
			</body>
		</body>
	</worldbody>
	<actuator>
		<motor ctrllimited="true" ctrlrange="-3 3" gear="100" joint="slider" name="slide" />
	</actuator>
</mujoco>
